Workbook

Sheet Anti
F1: Common [C] | I1: Common [C] | L1: Uncommon [UC]
B3: 1 | C3: C O M M O N | D3: CHA | F3: 140 | G3: Alternative Normality | I3: 120 | J3: Weird Whisperer | L3: 100 | M3: Excentricity | P3: 140 | Q3: Scarecrow | U3: 130 | V3: Harmless Fatale | Z3: 120 | AA3: Threatening Presence | AE3: 110 | AF3: Freakshow
D4: Non | F4: =F3 -> 140 | I4: =I3 -> 120 | L4: 100 | O4: Appearence | P4: CAR | Q4: Damn!, you are scary, your whole deamenor gives you that dangerous look and ungodly aura, and it can be a really useful sometimes | U4: CAR | V4: Despite your clear lack of charisma, you project a clear aura and image of begin has deadly as a hamster, this triggers protective instincts from people of the "oposite sex" which can be good or bad depending on the circumstance (bad beucase you look unreliable and good beucase you can inspire protective instincts), however anyone that falls into this image/prejudice actively will grant the user a circumstance bonus. its applied to both social and non-social bases circumstances, even a sneak attack will add a bonus. CANNOT be taken with Scarecrow Anti-Perk | Z4: CAR | AA4: You look as someone who is dangerous, perhaps a thug, perhaps a criminal or a madman ready to stab someone, in simple terms no one wants to be near you by simple fear of you freaking out in public, even animals will react accordingly and guards will often stop you to ask about your business | AE4: CAR | AF4: You cause natural aphaty and rejection from people, its not nesesarily your looks but also you deamenor and voice, all of it composes a very misleading image to the point where you would rather speak behind a curtain. You have a natural "Aggro" aura that confuses and drives anyone to be hostile toward you, this is not applicable to "declared allies" or allies who can identify the user, but most neutral units will be confused and disconserted
F5: =F4-25 -> 115 | I5: =I4-20 -> 100
D6: CHA | E6: Aparence | F6: 135 | G6: Scarecrow | I6: 115 | J6: Aggro Caller | L6: 100 | M6: Haunted Crow | P6: Common[C] Anti-Perk | Q6: * - CAR 120: cu | U6: Common[C] Anti-Perk | V6: * - CAR 110: cu | Z6: UnCommon[UC] Anti-Perk | AA6: * - CAR 100: c | AE6: Rare[R] Anti-Perk | AF6: * - BASE: en
D7: Non | F7: =F6 -> 135 | I7: 115 | L7: 100 | Q7: * - Counter: en | V7: * - Counter: en | AA7: * - Counter: Las | AF7: REQ: Intimidating Presence + Stereotyping
F8: =F7-25 -> 110 | I8: 100
B9: 2 | D9: CHA | E9: Thrill | F9: 130 | G9: Devil-s Luck | I9: 115 | J9: Dangerous Atraction | L9: 100 | M9: Dare-Devil | P9: 140 | Q9: Innocently Insensitive | U9: 130 | V9: Unbeliveable | Z9: 120 | AA9: Natural Menace | AE9: 110 | AF9: Sociophaty for Fun | AK9: AGI
D10: Non | F10: =F9 -> 130 | I10: 115 | L10: 100 | O10: Emphaty | P10: CAR | Q10: a Flawled capacity for emphaty in the ability to detect, decipher and comprehend emotion may be a blessing in disguise, you have a natural resistance toward charisma based attacks such as war cry, intimidation and charm | U10: CAR | V10: You try your hardest to tell someone the truth but you simply and plainly are rather shady looking and with face saying that "im a scammer", you are simply unbelibeable but this can work on your advantage as people will regard you as a uncertain factor | Z10: CAR | AA10: you project THAT image, you look shady as hell, as if you are scheming something, you are clearly the villian in people's eye. You gain natural reputation toward the vilified and rejections of society, your charisma works as if it was much higher | AE10: CAR | AF10: ?????? | AK10: - Lame
F11: =F10-25 -> 105 | I11: 100 | AK11: - Lucky Clumsy
D12: CHA | E12: Feeling | F12: 140 | G12: Nerd Rage | I12: 120 | J12: Euphoria | L12: 100 | M12: Jekil & Hyde | P12: Common[C] Anti-Perk | Q12: * - CAR 120: cu | U12: Common[C] Anti-Perk | V12: * - CAR 110: cu | Z12: UnCommon[UC] Anti-Perk | AA12: * - CAR 100: c | AE12: Rare[R] Anti-Perk | AF12: * - BASE: en | AK12: - Trembling nads
D13: Non | F13: =F12 -> 140 | I13: =I12 -> 120 | L13: 100 | Q13: * - Counter: en | V13: * - Counter: en | AA13: * - Counter: Las | AF13: REQ: Natural Menace + Dangerous Attraction | AK13: - Klurtz
F14: =F13-25 -> 115 | I14: =I13-20 -> 100 | AK14: - Slow Mo
B15: 3 | D15: CHA | E15: Comm | F15: 140 | G15: DeadPan | I15: 120 | J15: Insensitive | L15: 100 | M15: Unimportant | P15: 140 | Q15: Motormouth | U15: 130 | V15: Noise Cancel | Z15: 120 | AA15: The Bore | AE15: 110 | AF15: Gargoyle Mumbling
D16: Non | F16: =F15 -> 140 | I16: =I15 -> 120 | L16: 100 | O16: Communication | P16: CAR | Q16: you speak unnaturally fast, you mouth also moves before you think!, its easy to screw things up but in exchange you reduce the time used for the "Verbal" component of most actions, any pure verbal action will be reduced in execution by 60%, while any action with a partial verbal component is reduced by 30% in average. | U16: CAR | V16: Your words have a particular tone and accent which people find annoying, its like a screech in the background or a white noise that plays as you talk. However, your mouth has the power to cancel other charisma attacks or intercept sound based debacles. You got a group falling asleep for a hypnotic lullaby, then just talk normally and the effect will dminish or be cancelled altogether | Z16: CAR | AA16: This is a person whose conversation is so dull, you would rather watch paint dry for an hour than listen to them for a minute. This works like a charm as a Charisma based attack toward the "Willpower" attribute, temporarily reducing the enemy attribute and even softening any mental resilence by lowering the awareness | AE16: CAR | AF16: ??????
F17: =F16-25 -> 115 | I17: =I16-20 -> 100 | AJ17: cdc
D18: WIL | E18: Focus | F18: 140 | G18: Useful Compulsion | I18: 120 | J18: Positive Obsesion | L18: 100 | M18: Adictive Enlightment | P18: Common[C] Anti-Perk | Q18: * - CAR 120: cu | U18: Common[C] Anti-Perk | V18: * - CAR 110: cu | Z18: UnCommon[UC] Anti-Perk | AA18: * - CAR 100: c | AE18: Rare[R] Anti-Perk | AF18: * - BASE: en
D19: Non | F19: =F18 -> 140 | I19: =I18 -> 120 | L19: 100 | Q19: * - Counter: en | V19: * - Counter: en | AA19: * - Counter: Las | AF19: REQ: The Bore + Scarecrow
P21: 140 | Q21: Whisperer Chain | U21: 130 | V21: Silence is Gold | Z21: 120 | AA21: Stone Mask | AE21: 110 | AF21: Silent Accomplice
O22: Silence | P22: CAR | Q22: your words lose power the more you talk, anything more than 5 words makes your words become weak and dilluited as if your voice was drowned into a whisper. | U22: CAR | V22: When you are silent and not moving, you produce a special charisma based aura effect, this aura effect varies according to the other people mood, in other words, some people will see the person as scary and some will feel him begin imposing, while others will feel presured, its all in the imagination of the onlooker, however, the mood in the room will affect this effect in great measure. A character with high willpower score 350+ are inmune to this effect. This effect is mantained as long as the user is silent and his actions work in line with the target perception | Z22: CAR | AA22: Your face is disconected from your emotional side just enough so it becomes your personal trademark. your heart burns but your face never shows, this leads to a heightened dificulty on "Sense motive" against you and other skill that read the character mood a severe penalty to skills used to express your emotions | AE22: CAR | AF22: ?????
P24: Common[C] Anti-Perk | Q24: * - CAR 120: cu | U24: Common[C] Anti-Perk | V24: * - CAR 110: cu | Z24: UnCommon[UC] Anti-Perk | AA24: * - CAR 100: c | AE24: Rare[R] Anti-Perk | AF24: * - BASE: en
Q25: * - Counter: en | V25: * - Counter: en | AA25: * - Counter: Las | AF25: REQ: Stone Mask +Clown Ears
P27: 140 | Q27: Stereotyping | U27: 130 | V27: Clown Ears | Z27: 120 | AA27: Karmic Hideout | AE27: 110 | AF27: Almost Faceless
O28: Prejudice | P28: CAR | Q28: Whenever you can fall into a stereotype your mark believes in (such as that orcs are brutal and cruel, women are scared and helpless, or that halflings are all thieves, etc.), you end up fitting and flowing with it thus againing advantage in social instances. This bonus is not cumulative if several prejudices can be used at once. For example, if your mark believes that halflings are scared and helpless, and that women are also scared and helpless you will only gain one single prejudice type even if you have both qualities (woman and halfling in the example). but this breaks once you take a clear action that defies this notion. | U28: CAR | V28: you apear to be a natural clown in your responses and deamenor, and due to your low charisma this makes others perceive you as a joke. However in exchange people will become talkactive and easily confide in you, sometimes beyond their own will | Z28: CAR | AA28: you have such low charisma and your actions are so clearly directed with prejudice that they hide a single truth: your alignment becomes obscured, and it cannot be exactly judged from your actions. With the exception of clear cut actions such as murder most people will classify you as morally grey and have different views on your alignment and general disposition, this not only obscures the alignment itself but also some traits such as a killer bloodlust or a paladin goodness | AE28: CAR | AF28: ??????
P30: Common[C] Anti-Perk | Q30: * - CAR 120: cu | U30: Common[C] Anti-Perk | V30: * - CAR 110: cu | Z30: UnCommon[UC] Anti-Perk | AA30: * - CAR 100: c | AE30: Rare[R] Anti-Perk | AF30: * - BASE: en
Q31: * - Counter: en | V31: * - Counter: en | AA31: * - Counter: Las | AF31: REQ: Karmic Hideout + Bland
P33: 140 | Q33: Dangerous Atraction | U33: 130 | V33: Bland | Z33: 120 | AA33: Innate Troll | AE33: 110 | AF33: Storm Caller
P34: CAR | Q34: You tend to attract the attention of the wrong crowd, and even when doing nothing will become socially interwited with people of questionable nature and dangerous inclination | U34: CAR | V34: You have no features, no distinctive presence you are almost forgeteable, and this can become a blessing to you. Bland makes the user hard to identify and easily pass unnoticed when walking in a crowd. You gain a passive stealth bonus when moving in a group of people, moreover, you add a hard penalty to identify or mark you | Z34: CAR | AA34: you easily speak the wrong things and have the uncanny nature to call into social problems, you will make exactly the wrong comment at the wrong time, and sometimes unknownly you will simply step on the proverbial dragons tail just by doing something completly mundane, its a curse and sometimes a boon | AE34: CAR | AF34: ????
O35: Magnetism
P36: Common[C] Anti-Perk | Q36: * - CAR 120: cu | U36: Common[C] Anti-Perk | V36: * - CAR 110: cu | Z36: UnCommon[UC] Anti-Perk | AA36: * - CAR 100: c | AE36: Rare[R] Anti-Perk | AF36: * - BASE: en
Q37: * - Counter: en | V37: * - Counter: en | AA37: * - Counter: Las | AF37: REQ: Innate Troll + Innocently Insensitive
F38: =F19-25 -> 115 | I38: =I19-20 -> 100
B39: 4 | D39: WIL | E39: Cowardice | F39: 135 | G39: Practical Cowardice | L39: 100 | M39: Fear Trigger | P39: 140 | Q39: Clever Idiot | U39: 130 | V39: Lucky Idiot | Z39: 120
D40: Non | F40: =F39 -> 135 | L40: 100 | P40: INT | U40: INT | V40: The Fool's strength is almost a supernatural fortune bordering on Karma. Since The Fool is such a person, nothing bad happens to him | Z40: INT
F41: =F40-25 -> 110 | O41: Idiot | AE41: 100
D42: WIL | F42: 135 | L42: 100 | M42: Curse Magnet | P42: Common[C] Anti-Perk | Q42: * - INT 115: cu | U42: Common[C] Anti-Perk | V42: * - CAR 100: cu | Z42: UnCommon[UC] Anti-Perk | AA42: * - CAR 100: c | AE42: INT
D43: Non | L43: 100 | Q43: * - Counter: en | V43: * - Counter: en | AA43: * - Counter: Las
AE44: Rare[R] Anti-Perk | AF44: * - BASE: en
B45: 5 | D45: WIL | L45: 100 | P45: 140 | Q45: Primal Impulse | U45: 130 | Z45: 120 | AF45: * - Counter: en
D46: Non | L46: 100 | O46: Instinct | P46: INT | Q46: La razon bloquea el camino hacia la naturaleza instintiva, interna y primitiva, el impulso primal conecta con los antiguos instinto dormidos para bien o para mal | U46: INT | Z46: INT
...

Sheet Groups
AR4: 0 | AS4: =IFERROR(INDEX($C$5:$C$64,AR4*12+1),INDEX($M$5:$M$64,(AR4-4)*12+1)) -> WARRIOR | AT4: =CONCATENATE(LEFT(AS4,1),MID(LOWER(AS4),2,LEN(AS4))) -> Warrior
A5: 1 | C5: WARRIOR | D5: Melee Weapons Handling | H5: STR | I5: AGI | J5: STR- BODY - SPRT | M5: BRAWLER | N5: Brawling | R5: AGI | T5: AGI - BODY - SPRT | AR5: 1 | AS5: =IFERROR(INDEX($C$5:$C$64,AR5*12+1),INDEX($M$5:$M$64,(AR5-4)*12+1)) -> ROUGE | AT5: =CONCATENATE(LEFT(AS5,1),MID(LOWER(AS5),2,LEN(AS5))) -> Rouge
A6: 2 | Y6: =D9 -> Athletism | AB6: =H9 -> AGI | AC6: =COUNTIF($D$5:$Q$64,Y6)+COUNTIF($D$69:$V$149,Y6) -> 2 | AD6: =C5 -> WARRIOR | AF6: =M5 -> BRAWLER | AH6: =IF(IFNA(VLOOKUP(Y6,$Y7:Y$70,1,FALSE),"-")=Y6,"Duplicate","-") -> - | AK6: Athletism | AN6: AGI | AR6: 2 | AS6: =IFERROR(INDEX($C$5:$C$64,AR6*12+1),INDEX($M$5:$M$64,(AR6-4)*12+1)) -> MAGE | AT6: =CONCATENATE(LEFT(AS6,1),MID(LOWER(AS6),2,LEN(AS6))) -> Mage
A7: 3 | D7: Heavy Armor Handling | H7: STR | N7: Still Mind, Focus | R7: WIL | Y7: =S108 -> Intimidation | AB7: =W108 -> WIL | AC7: =COUNTIF($D$5:$Q$64,Y7)+COUNTIF($D$69:$V$149,Y7) -> 2 | AD7: =C5 -> WARRIOR | AH7: =IF(IFNA(VLOOKUP(Y7,$Y8:Y$70,1,FALSE),"-")=Y7,"Duplicate","-") -> - | AK7: Hide | AN7: AGI | AR7: 3 | AS7: =IFERROR(INDEX($C$5:$C$64,AR7*12+1),INDEX($M$5:$M$64,(AR7-4)*12+1)) -> SORCEROR | AT7: =CONCATENATE(LEFT(AS7,1),MID(LOWER(AS7),2,LEN(AS7))) -> Sorceror
A8: 4 | Y8: =D13 -> Discipline | AB8: =H13 -> WIL | AC8: =COUNTIF($D$5:$Q$64,Y8)+COUNTIF($D$69:$V$149,Y8) -> 2 | AD8: =C5 -> WARRIOR | AF8: =C53 -> PRIEST | AH8: =IF(IFNA(VLOOKUP(Y8,$Y9:Y$70,1,FALSE),"-")=Y8,"Duplicate","-") -> - | AK8: Sleight of Hand | AN8: AGI | AR8: 4 | AS8: =IFERROR(INDEX($C$5:$C$64,AR8*12+1),INDEX($M$5:$M$64,(AR8-4)*12+1)) -> PRIEST | AT8: =CONCATENATE(LEFT(AS8,1),MID(LOWER(AS8),2,LEN(AS8))) -> Priest
A9: 5 | D9: Athletism | H9: AGI | N9: Discipline | R9: WIL | Y9: =D21 -> Alert | AB9: =H21 -> PER | AC9: =COUNTIF($D$5:$Q$64,Y9)+COUNTIF($D$69:$V$149,Y9) -> 2 | AD9: =C17 -> ROUGE | AH9: =IF(IFNA(VLOOKUP(Y9,$Y10:Y$70,1,FALSE),"-")=Y9,"Duplicate","-") -> - | AK9: Dismantle | AN9: AGI | AR9: 5 | AS9: =IFERROR(INDEX($C$5:$C$64,AR9*12+1),INDEX($M$5:$M$64,(AR9-4)*12+1)) -> EXPLORER | AT9: =CONCATENATE(LEFT(AS9,1),MID(LOWER(AS9),2,LEN(AS9))) -> Explorer
A10: 6 | Y10: =D25 -> Hide | AB10: =H25 -> AGI | AC10: =COUNTIF($D$5:$Q$64,Y10)+COUNTIF($D$69:$V$149,Y10) -> 2 | AD10: =C17 -> ROUGE | AF10: =M17 -> EXPLORER | AH10: =IF(IFNA(VLOOKUP(Y10,$Y11:Y$70,1,FALSE),"-")=Y10,"Duplicate","-") -> - | AK10: Riding | AN10: AGI | AR10: 6 | AS10: =IFERROR(INDEX($C$5:$C$64,AR10*12+1),INDEX($M$5:$M$64,(AR10-4)*12+1)) -> BARD | AT10: =CONCATENATE(LEFT(AS10,1),MID(LOWER(AS10),2,LEN(AS10))) -> Bard
A11: 7 | D11: Battle | H11: PER | N11: Rest | R11: STR | Y11: =D33 -> Spellcraft | AB11: =H33 -> PER | AC11: =COUNTIF($D$5:$Q$64,Y11)+COUNTIF($D$69:$V$149,Y11) -> 2 | AD11: =C29 -> MAGE | AF11: =K87 -> Mystic | AH11: =IF(IFNA(VLOOKUP(Y11,$Y12:Y$70,1,FALSE),"-")=Y11,"Duplicate","-") -> - | AK11: Intimidation | AN11: CAR | AR11: 7 | AS11: =IFERROR(INDEX($C$5:$C$64,AR11*12+1),INDEX($M$5:$M$64,(AR11-4)*12+1)) | AT11: =CONCATENATE(LEFT(AS11,1),MID(LOWER(AS11),2,LEN(AS11)))
A12: 8 | Y12: =D37 -> Mental Focus | AB12: =H37 -> WIL | AC12: =COUNTIF($D$5:$Q$64,Y12)+COUNTIF($D$69:$V$149,Y12) -> 3 | AD12: =C29 -> MAGE | AF12: =C81 -> Showman | AH12: =IF(IFNA(VLOOKUP(Y12,$Y13:Y$70,1,FALSE),"-")=Y12,"Duplicate","-") -> - | AK12: Spirit Sensitivity | AN12: CAR
A13: 9 | D13: Discipline | H13: WIL | I13: STR | N13: Athletism | R13: AGI | Y13: =D35 -> Magic Obj | AB13: =H35 -> INT | AC13: =COUNTIF($D$5:$Q$64,Y13)+COUNTIF($D$69:$V$149,Y13) -> 2 | AD13: =C29 -> MAGE | AH13: =IF(IFNA(VLOOKUP(Y13,$Y14:Y$70,1,FALSE),"-")=Y13,"Duplicate","-") -> - | AK13: Bluff | AN13: CAR
A14: 10 | Y14: =D57 -> Spirit Sensitivity | AB14: =H57 -> CAR | AC14: =COUNTIF($D$5:$Q$64,Y14)+COUNTIF($D$69:$V$149,Y14) -> 2 | AD14: =C53 -> PRIEST | AH14: =IF(IFNA(VLOOKUP(Y14,$Y15:Y$70,1,FALSE),"-")=Y14,"Duplicate","-") -> - | AK14: Perform | AN14: CAR
A15: 11 | Y15: =D59 -> Healing | AB15: =H59 -> WIL | AC15: =COUNTIF($D$5:$Q$64,Y15)+COUNTIF($D$69:$V$149,Y15) -> 3 | AD15: =C53 -> PRIEST | AH15: =IF(IFNA(VLOOKUP(Y15,$Y16:Y$70,1,FALSE),"-")=Y15,"Duplicate","-") -> - | AK15: Animal Empathy | AN15: CAR
A16: 12 | Y16: =D23 -> Bluff | AB16: =H23 -> CAR | AC16: =COUNTIF($D$5:$Q$64,Y16)+COUNTIF($D$69:$V$149,Y16) -> 2 | AD16: =M5 -> BRAWLER | AF16: =K81 -> Minstrel | AH16: =IF(IFNA(VLOOKUP(Y16,$Y17:Y$70,1,FALSE),"-")=Y16,"Duplicate","-") -> - | AK16: Diplomacy | AN16: CAR
A17: 13 | C17: ROUGE | D17: Light Weapons Handling | H17: AGI | J17: AGI -BODY - MIND | M17: EXPLORER | N17: Projectile Weapons Handling | R17: PER | T17: PER - BODY - MIND | Y17: =N11 -> Rest | AB17: =R11 -> STR | AC17: =COUNTIF($D$5:$Q$64,Y17)+COUNTIF($D$69:$V$149,Y17) -> 2 | AD17: =M5 -> BRAWLER | AF17: =M53 -> DRUID | AH17: =IF(IFNA(VLOOKUP(Y17,$Y18:Y$70,1,FALSE),"-")=Y17,"Duplicate","-") -> Duplicate | AK17: Haggle | AN17: CAR
Y18: =N23 -> Trapper | AB18: =R23 -> INT | AC18: =COUNTIF($D$5:$Q$64,Y18)+COUNTIF($D$69:$V$149,Y18) -> 2 | AD18: =M17 -> EXPLORER | AH18: =IF(IFNA(VLOOKUP(Y18,$Y19:Y$70,1,FALSE),"-")=Y18,"Duplicate","-") -> - | AK18: Acting | AN18: CAR
D19: Light Armor Handling | H19: STR | I19: AGI | N19: Light Armor Handling | R19: STR | AD19: =M17 -> EXPLORER | AH19: =IF(IFNA(VLOOKUP(Y19,$Y20:Y$70,1,FALSE),"-")=Y19,"Duplicate","-") -> - | AK19: Temptation | AN19: CAR
Y20: =N33 -> Sleight of Hand | AB20: =R33 -> AGI | AC20: =COUNTIF($D$5:$Q$64,Y20)+COUNTIF($D$69:$V$149,Y20) -> 2 | AD20: =M29 -> BARD | AF20: =R69 -> Thief | AH20: =IF(IFNA(VLOOKUP(Y20,$Y21:Y$70,1,FALSE),"-")=Y20,"Duplicate","-") -> - | AK20: Magic Obj | AN20: INT
D21: Alert | H21: PER | N21: Dismantle | R21: AGI | Y21: =N35 -> Perform | AB21: =R35 -> CAR | AC21: =COUNTIF($D$5:$Q$64,Y21)+COUNTIF($D$69:$V$149,Y21) -> 2 | AD21: =M29 -> BARD | AF21: =K81 -> Minstrel | AH21: =IF(IFNA(VLOOKUP(Y21,$Y22:Y$70,1,FALSE),"-")=Y21,"Duplicate","-") -> - | AK21: Trapper | AN21: INT
Y22: =L71 -> Culture Lore | AB22: INT | AC22: =COUNTIF($D$5:$Q$64,Y22)+COUNTIF($D$69:$V$149,Y22) -> 2 | AD22: =M29 -> BARD | AF22: =K81 -> Minstrel | AH22: =IF(IFNA(VLOOKUP(Y22,$Y23:Y$70,1,FALSE),"-")=Y22,"Duplicate","-") -> - | AK22: Culture Lore | AN22: INT
D23: Bluff | H23: CAR | N23: Trapper | R23: INT | Y23: =S112 -> Wilderness | AB23: WIL | AC23: =COUNTIF($D$5:$Q$64,Y23)+COUNTIF($D$69:$V$149,Y23) -> 3 | AD23: =M53 -> DRUID | AF23: =R112 -> Survivalist | AH23: =IF(IFNA(VLOOKUP(Y23,$Y24:Y$70,1,FALSE),"-")=Y23,"Duplicate","-") -> - | AK23: Astrology | AN23: INT
Y24: =L91 -> Astrology | AB24: =P91 -> INT | AC24: =COUNTIF($D$5:$Q$64,Y24)+COUNTIF($D$69:$V$149,Y24) -> 3 | AD24: =M53 -> DRUID | AF24: =K87 -> Mystic | AH24: =IF(IFNA(VLOOKUP(Y24,$Y25:Y$70,1,FALSE),"-")=Y24,"Duplicate","-") -> - | AK24: Court | AN24: INT
D25: Hide | H25: AGI | N25: Alert | R25: PER | Y25: Battle | AB25: PER | AC25: =COUNTIF($D$5:$Q$64,Y25)+COUNTIF($D$69:$V$149,Y25) -> 2 | AH25: =IF(IFNA(VLOOKUP(Y25,$Y26:Y$70,1,FALSE),"-")=Y25,"Duplicate","-") -> - | AK25: Craft | AN25: INT
Y26: Cooking | AB26: =H69 -> WIL | AC26: =COUNTIF($D$5:$Q$64,Y26)+COUNTIF($D$69:$V$149,Y26) -> 2 | AH26: =IF(IFNA(VLOOKUP(Y26,$Y27:Y$70,1,FALSE),"-")=Y26,"Duplicate","-") -> - | AK26: Formal Magics | AN26: INT
Y27: Animal Empathy | AB27: =IFNA(VLOOKUP(Y27,$L$69:$P$92,5,FALSE),VLOOKUP(Y27,$D$69:$H$80,5,FALSE)) -> CAR | AC27: =COUNTIF($D$5:$Q$64,Y27)+COUNTIF($D$69:$V$149,Y27) -> 4 | AH27: =IF(IFNA(VLOOKUP(Y27,$Y28:Y$70,1,FALSE),"-")=Y27,"Duplicate","-") -> - | AK27: Herbalism | AN27: INT
Y28: Apraisal | AB28: =H91 -> PER | AC28: =COUNTIF($D$5:$Q$64,Y28)+COUNTIF($D$69:$V$149,Y28) -> 2 | AH28: =IF(IFNA(VLOOKUP(Y28,$Y29:Y$70,1,FALSE),"-")=Y28,"Duplicate","-") -> - | AK28: Knowledge (Specific) | AN28: INT
C29: MAGE | D29: Basic Mana Discipline | H29: INT | J29: MIND2 | M29: BARD | N29: Mana Sensitivity | R29: WIL | T29: CAR - SPR - BODY | Y29: Climbing | AB29: =W73 -> STR | AC29: =COUNTIF($D$5:$Q$64,Y29)+COUNTIF($D$69:$V$149,Y29) -> 2 | AH29: =IF(IFNA(VLOOKUP(Y29,$Y30:Y$70,1,FALSE),"-")=Y29,"Duplicate","-") -> - | AK29: Linguistics | AN29: INT
AH30: =IF(IFNA(VLOOKUP(Y30,$Y31:Y$70,1,FALSE),"-")=Y30,"Duplicate","-") -> - | AK30: Mechanics | AN30: INT
D31: Mana Sensitivity | H31: PER | I31: WIL | N31: Melee Weapons Handling | R31: STR | Y31: Craft | AB31: =P93 -> INT | AC31: =COUNTIF($D$5:$Q$64,Y31)+COUNTIF($D$69:$V$149,Y31) -> 1 | AH31: =IF(IFNA(VLOOKUP(Y31,$Y32:Y$70,1,FALSE),"-")=Y31,"Duplicate","-") -> - | AK31: Lockpick | AN31: INT
Y32: Diplomacy | AB32: =IFNA(VLOOKUP(Y32,$L$69:$P$92,5,FALSE),VLOOKUP(Y32,$D$69:$H$80,5,FALSE)) -> #N/A | AC32: =COUNTIF($D$5:$Q$64,Y32)+COUNTIF($D$69:$V$149,Y32) -> 2 | AH32: =IF(IFNA(VLOOKUP(Y32,$Y33:Y$70,1,FALSE),"-")=Y32,"Duplicate","-") -> - | AK32: Alert | AN32: PER
D33: Spellcraft | H33: PER | N33: Sleight of Hand | R33: AGI | Y33: Dismantle | AB33: =IFNA(VLOOKUP(Y33,$L$69:$P$92,5,FALSE),VLOOKUP(Y33,$D$69:$H$80,5,FALSE)) -> #N/A | AC33: =COUNTIF($D$5:$Q$64,Y33)+COUNTIF($D$69:$V$149,Y33) -> 2 | AH33: =IF(IFNA(VLOOKUP(Y33,$Y34:Y$70,1,FALSE),"-")=Y33,"Duplicate","-") -> - | AK33: Spellcraft | AN33: PER
Y34: Farming | AB34: =IFNA(VLOOKUP(Y34,$L$69:$P$92,5,FALSE),VLOOKUP(Y34,$D$69:$H$80,5,FALSE)) -> WIL | AC34: =COUNTIF($D$5:$Q$64,Y34)+COUNTIF($D$69:$V$149,Y34) -> 1 | AH34: =IF(IFNA(VLOOKUP(Y34,$Y35:Y$70,1,FALSE),"-")=Y34,"Duplicate","-") -> - | AK34: Battle | AN34: PER
D35: Magic Obj | H35: INT | N35: Perform | R35: CAR | Y35: Formal Magics | AB35: =P87 -> INT | AC35: =COUNTIF($D$5:$Q$64,Y35)+COUNTIF($D$69:$V$149,Y35) -> 1 | AH35: =IF(IFNA(VLOOKUP(Y35,$Y36:Y$70,1,FALSE),"-")=Y35,"Duplicate","-") -> - | AK35: Apraisal | AN35: PER
Y36: Haggle | AB36: =H89 -> CAR | AC36: =COUNTIF($D$5:$Q$64,Y36)+COUNTIF($D$69:$V$149,Y36) -> 2 | AH36: =IF(IFNA(VLOOKUP(Y36,$Y37:Y$70,1,FALSE),"-")=Y36,"Duplicate","-") -> - | AK36: Investigation | AN36: PER
D37: Mental Focus | H37: WIL | N37: Diplomacy | R37: CAR | Y37: HandiCraft | AB37: =W114 -> STR | AC37: =COUNTIF($D$5:$Q$64,Y37)+COUNTIF($D$69:$V$149,Y37) -> 2 | AH37: =IF(IFNA(VLOOKUP(Y37,$Y38:Y$70,1,FALSE),"-")=Y37,"Duplicate","-") -> - | AK37: Sense Motive | AN37: PER
Y38: Herbalism | AB38: =H97 -> INT | AC38: =COUNTIF($D$5:$Q$64,Y38)+COUNTIF($D$69:$V$149,Y38) -> 2 | AH38: =IF(IFNA(VLOOKUP(Y38,$Y39:Y$70,1,FALSE),"-")=Y38,"Duplicate","-") -> - | AK38: Streetwise | AN38: PER
Y39: Inclemence | AB39: =W85 -> STR | AC39: =COUNTIF($D$5:$Q$64,Y39)+COUNTIF($D$69:$V$149,Y39) -> 2 | AH39: =IF(IFNA(VLOOKUP(Y39,$Y40:Y$70,1,FALSE),"-")=Y39,"Duplicate","-") -> - | AK39: Tracking | AN39: PER
Y40: Investigation | AB40: =IFNA(VLOOKUP(Y40,$L$69:$P$92,5,FALSE),VLOOKUP(Y40,$D$69:$H$80,5,FALSE)) -> PER | AC40: =COUNTIF($D$5:$Q$64,Y40)+COUNTIF($D$69:$V$149,Y40) -> 3 | AH40: =IF(IFNA(VLOOKUP(Y40,Y53:$Y$70,1,FALSE),"-")=Y40,"Duplicate","-") -> - | AK40: Rest | AN40: STR
C41: SORCEROR | D41: Basic Mana Discipline | H41: CAR
D45: Astrology | H45: INT
D47: Animal Empathy | H47: CAR
...

Sheet List
C3: Core Skills
B5: 1 | C5: Brawling | E5: =IFNA(VLOOKUP(C5,Groups!$D$5:$H$62,5,FALSE),VLOOKUP(C5,Groups!$N$5:$R$62,5,FALSE)) -> AGI
B6: 2 | C6: Light Weapons Handling | E6: =IFNA(VLOOKUP(C6,Groups!$D$5:$H$62,5,FALSE),VLOOKUP(C6,Groups!$N$5:$R$62,5,FALSE)) -> AGI | H6: Basic lv struct
B7: 3 | C7: Holy Light, Faith | E7: =IFNA(VLOOKUP(C7,Groups!$D$5:$H$62,5,FALSE),VLOOKUP(C7,Groups!$N$5:$R$62,5,FALSE)) -> CAR
B8: 4 | C8: Nature, Focus | E8: =IFNA(VLOOKUP(C8,Groups!$D$5:$H$62,5,FALSE),VLOOKUP(C8,Groups!$N$5:$R$62,5,FALSE)) -> CAR | H8: 1. Action open - raise 1
B9: 5 | C9: Basic Mana Discipline | E9: =IFNA(VLOOKUP(C9,Groups!$D$5:$H$62,5,FALSE),VLOOKUP(C9,Groups!$N$5:$R$62,5,FALSE)) -> INT | H9: 2. Skill check+1 -
B10: 6 | C10: Mana Sensitivity | E10: =IFNA(VLOOKUP(C10,Groups!$D$5:$H$62,5,FALSE),VLOOKUP(C10,Groups!$N$5:$R$62,5,FALSE)) -> PER | H10: 3. Skill performance+1 - item allowance
B11: 7 | C11: Projectile Weapons Handling | E11: =IFNA(VLOOKUP(C11,Groups!$D$5:$H$62,5,FALSE),VLOOKUP(C11,Groups!$N$5:$R$62,5,FALSE)) -> PER | H11: 4. Skill check+2 -
B12: 8 | C12: Heavy Armor Handling | E12: =IFNA(VLOOKUP(C12,Groups!$D$5:$H$62,5,FALSE),VLOOKUP(C12,Groups!$N$5:$R$62,5,FALSE)) -> STR | H12: 5. Skill Prof - Greater Check+1
B13: 9 | C13: Light Armor Handling | E13: =IFNA(VLOOKUP(C13,Groups!$D$5:$H$62,5,FALSE),VLOOKUP(C13,Groups!$N$5:$R$62,5,FALSE)) -> STR | I13: Skill becomes upgradeable 1
B14: 10 | C14: Melee Weapons Handling | E14: =IFNA(VLOOKUP(C14,Groups!$D$5:$H$62,5,FALSE),VLOOKUP(C14,Groups!$N$5:$R$62,5,FALSE)) -> STR | H14: 6. 1st Feat Requiered
B15: 11 | C15: Piety | E15: =IFNA(VLOOKUP(C15,Groups!$D$5:$H$62,5,FALSE),VLOOKUP(C15,Groups!$N$5:$R$62,5,FALSE)) -> WIL | I15: Action Enhance - greater perform
B16: 12 | C16: Still Mind, Focus | E16: =IFNA(VLOOKUP(C16,Groups!$D$5:$H$62,5,FALSE),VLOOKUP(C16,Groups!$N$5:$R$62,5,FALSE)) -> WIL | H16: 7. Skill performance+2 - raise 2
I17: Skill becomes upgradeable 2
H18: 8. Skill check+3 - attributes skill restric
C19: Aditional Skills | H19: 9. Skill performance+4 -
I20: Skill becomes upgradeable 3
B21: 1 | C21: Athletism | E21: =VLOOKUP(C21,Groups!$AK$6:$AN$64,4,FALSE) -> AGI | H21: 10. 2nd Feat Requiered
B22: 2 | C22: Dismantle | E22: =VLOOKUP(C22,Groups!$AK$6:$AN$64,4,FALSE) -> AGI | I22: Skill prof+, Mastery perk, Greater Check+2
B23: 3 | C23: Hide | E23: =VLOOKUP(C23,Groups!$AK$6:$AN$64,4,FALSE) -> AGI
B24: 4 | C24: Riding | E24: =VLOOKUP(C24,Groups!$AK$6:$AN$64,4,FALSE) -> AGI
B25: 5 | C25: Sleight of Hand | E25: =VLOOKUP(C25,Groups!$AK$6:$AN$64,4,FALSE) -> AGI
B26: 6 | C26: Acting | E26: =VLOOKUP(C26,Groups!$AK$6:$AN$64,4,FALSE) -> CAR
B27: 7 | C27: Animal Empathy | E27: =VLOOKUP(C27,Groups!$AK$6:$AN$64,4,FALSE) -> CAR
B28: 8 | C28: Bluff | E28: =VLOOKUP(C28,Groups!$AK$6:$AN$64,4,FALSE) -> CAR
B29: 9 | C29: Diplomacy | E29: =VLOOKUP(C29,Groups!$AK$6:$AN$64,4,FALSE) -> CAR
B30: 10 | C30: Haggle | E30: =VLOOKUP(C30,Groups!$AK$6:$AN$64,4,FALSE) -> CAR
B31: 11 | C31: Intimidation | E31: =VLOOKUP(C31,Groups!$AK$6:$AN$64,4,FALSE) -> CAR
B32: 12 | C32: Perform | E32: =VLOOKUP(C32,Groups!$AK$6:$AN$64,4,FALSE) -> CAR
B33: 13 | C33: Spirit Sensitivity | E33: =VLOOKUP(C33,Groups!$AK$6:$AN$64,4,FALSE) -> CAR
B34: 14 | C34: Astrology | E34: =VLOOKUP(C34,Groups!$AK$6:$AN$64,4,FALSE) -> INT
... B63: 43 | C63: Wayfarer | E63: =VLOOKUP(C63,Groups!$AK$6:$AN$64,4,FALSE) -> WIL

Sheet Sheet1

Sheet Skill Detail
C3: DISCIPLINE | E3: =VLOOKUP(C3,List!$C$5:$E$63,3,FALSE) -> WIL | L3: HIDE | N3: =VLOOKUP(L3,List!$C$5:$E$63,3,FALSE) -> AGI | U3: ATHLETISM | W3: =VLOOKUP(U3,List!$C$5:$E$63,3,FALSE) -> AGI | AD3: Melee Weapons | AF3: STR
C4: Action: | L4: Action: | U4: Action: | AD4: Action:
C5: Lv 1 | D5: Combat focus - resist fear and cohesion based spirit attacks automatically when in battle | M5: Hide in Cover - hide using "Heavy obstacles" such as walls, solid structures, etc. You need to cover your whole body to make it work | V5: Action Man: perform enhanced physical action such as Running, Jumping, etc. After the action there is a temporal fatigue debuff of 1 dice penalty, stackable | AE5: Melee Combat I:
C6: LV 6 | D6: C. Focus II - when in combat defend against distractions automatically | M6: Hide in Cover II - Hide using "Light obstacles" such as thin structures and furniture, you need to cover your whole body to make it work | V6: A.Man II - you can perform a extended Athetism action, until you stop there is no sudden fatigue penalty. Stopping means to have one round where you do not perform athetism actions or you fail your athetism skill check | AE6: Melee Combat II: | AL6: Action Man: perform enhanced physical action such as Running, Jumping, etc. After the action there is a temporal fatigue debuff of 1 dice penalty, stackable
C7: Lv 10 | D7: C. Focus III - react to fear outside of battle with a saving roll bonus | M7: Hide in Cover III - as long as you cover your body with a heavy or light obstacle at 75% it is considered covered and may be hidden | V7: A.Man III - allows to resist and reject the temporal fatigue defuff with a body saving roll, however next fatigue roll becomes harder to resist | AE7: Melee Combat III: | AL7: A.Man II - you can perform a extended Athetism action, until you stop there is no sudden fatigue penalty. Stopping means to have one round where you do not perform athetism actions or you fail your athetism skill check
C8: Evolution: | L8: Evolution: | U8: Evolution: | AD8: Evolution:
D9: Bravery(T1) | M9: Camoflage(T1) | V9: Sprinter(T1) | AE9: Pikemen Technique (T1)
D10: Soldiering (T2) | M10: Cloak&Dagger(T2) | V10: Acrobacy(T2) | AE10: Heavy Blade Technique (T1)
D11: Martial Temperance (T3) | M11: Hide in Plain Sight (T3) | V11: Heightened Balance (T3) | AE11: Battle Club Technique (T1)
D12: Warmonger (Rare) | M12: Unremarkable (Rare) | V12: Marathon (Rare) | AE12: Light Blade Technique (T1)
C13: Perform(1-5) | L13: Perform(1-4) | U13: Perform(1-4) | AE13: Footman Technique (T2)
D14: Start - Resist by 5 | M14: Start - Hide Cover Dificulty by 10 | V14: Start - Improve 25% of physical action | AE14: Heavy Soldier Technique (T2)
D15: 1. Resist by 10 | M15: 1. Hide Cover Dificulty by 15 | V15: 1. Improve 50% of physical action | AE15: Light Calvalry Technique (T2)
D16: 2. Skill Crit: On a skill check of 40 or more, add +10 to Resist Score | M16: 2. Skill Crit: On a skill check of 40 or more, add +10 to Hide Score | V16: 2. Skill Crit: On a skill check of 40 or more, add +50% to physical action performance | AE16: Barbarian Vandal Technique (T3)
D17: 3. Resist by 15 | M17: 3. Hide Cover Dificulty by 20 | V17: 3. Improve 75% of physical action | AE17: Guardian Soldier Technique (T3)
D18: G.Perf - Reaction: you gain a +5 morale bonus on attack rolls and weapon damage rolls the fear affect on you for 1 round. Non Stackable | M18: G.Perf - ?? | V18: G.Perf - Reduces the amount of Fatigue produced by a Highly physical action | AE18: Twin Blade Technique (Rare)
E19: Reaction: Whenever a fear effect targets you and fails to affect you | M19: 4. Hide Cover Dificulty by 25 | V19: 4. Improve 100% of physical action | AE19: Oriental Spear Technique (Rare)
D20: 4. Resist by 20 | M20: 5. Skill Crit: On a skill check of 50 or more, add +10 to Hide Score | V20: 2. Skill Crit: On a skill check of 50 or more, add +100% to physical action performance | AD20: Perform(1-4)
D21: 5. Skill Crit 2: On a skill check of 50 or more, add +15 to Resist Score, Reaction doubles bonus and it last for 3 rounds | AE21: Start -
C22: Proficiency (1-7) | L22: Proficiency (1-7) | U22: Proficiency (1-7)
D23: 1. Discipline item: well mantained and functional battle gear grants +1 per piece to skill check up to a max of +3 | M23: 1. Hide Item: Hide skills can be used | V23: 1. Athletism Item: Specific footwear item can boost athletism
D24: 2. Group Bravery: When fighting in groups the morale of others may strenghten your will based skills | M24: 2. Step in shadows - shadows grant bonus | V24: 2.
D25: 3. Soldier's Resilence: The character's focus and discipline allow them to reduce fatigue penalty temporarily for 1 scene using discipline skill checks | M25: 3. Hide in shadows - deep shadows are used as a light cover obstacle | V25: 3.
D26: 4. Against The Wall: When the character is bellow 25% of his HP, his abilities explode into an ability boost during a number of rounds equal to your will/50 | M26: 4. Peek a boo - you peek around objects without loosing cover | V26: 2.
D27: 5. Stoic reticence: your discipline skill will trigger automatically even against ambrushes and other effects that you are not aware of., however, you still need to be on guard and alert to danger for this to happen so a complete ambrush will still leave you defenseless | M27: 5. Shadow switch - you can change covers as a free action when no one is looking within 3 mts. Only once per round | V27: 3.
D28: 6. Combat Discipline: The character's discipline in combat allows them to slightly reduce non-supernatural physical damage they are aware of based on the WILL score | M28: 6. Quick shadow - you can exit stealth cover to perform a single action such as steal or attack within 3 mts then return to your stealth on the same round | V28: 2.
D29: 7. Iron Heart: your mind and heart have been trained throughtly, in any mind-affecting effect over you which has a skill check with less than 40, you will reduce one rank in the effect or otherwise halve the duration of the effect. this only works in mind or enchantment skills which are rejected using will or spirit based rolls | M29: 7. One with shadows - when in shadows special perk become active | V29: 3.
C32: Healing | E32: =VLOOKUP(C32,List!$C$5:$E$63,3,FALSE) -> WIL | L32: Battle | N32: =VLOOKUP(L32,List!$C$5:$E$63,3,FALSE) -> PER | U32: Magic Obj | W32: INT | AD32: Mana Sensitivity | AF32: WIL
C33: Action: | L33: Action: | U33: Action: | AD33: Action:
D34: Patching : During a "Short Rest" (aprox 2hrs) period, you can recover additional (1k1) to target, it works only once per target after any "Long Rest" (8hrs), multiple healings cannot be stacked together. You can only heal as many as your WILL/50 people during a single short rest, while still resting yourself. otherwise, you can manage twice as much people but with no rest and adding a permanent fatigue penalty debuff | M34: Battle Tactics : in combat battle tactics can be used to spot combat oportunities and asset when the enemy is working to obtain an advantage. For example: in the next round, if you do not move from this area you will be blocked off from escape, and one round later you will be surrounded. A simple tactical superiority will offer additional circumstantial bonus to the user during a specific frame of time, on the other hand a obtaining a clear "advantage" such surrounding, or a high ground with a ranged weapon will either have the user roll twice and choose the best roll or directly take away dice from the target | V34: Magic Exec I: you can activate and use most "useable" and "non bonded" magic items. It takes 10-20 rounds to sync with the magic item for the first time and from then on, 1-3 round of syncing before using the magic object after that. You need to spend 1mp at least to activate a magic item, a character incapable of providing at least this much cannot activate the item. Please keep in mind that different magic items have a different "magic obj" level to be used and some requiere far more MP to be activated. | AE34: Mana Trigger: As a Full-Round Action, you can use this ability to actively sense other Mana-users out to a range of 1 meters x compound skill level. If you succeed on a DC 15 Mana sensitivity check, you know how many Mana-users are within range, their approximate distance and direction from you. Another Mana-user within range can try to conceal his or her presence from you by making an opposed Mana Sensitivity check. The higher and more vulgar the display of mana the easier is to sense and localize this presence, you can imagine it as a sixth sence which triggers automatically in reaction to mana. This is very useful to find mana rich locations, items and even to react to sudden mana attacks such as mana based traps. This action is limited to "ACTIVE" mana skills which are cast or target near the user, and will not register PASSIVE mana skills or abilities which are already at work continuosly beforehand
D35: Patching II : Reduces penalty when dealing with open wound injuries such as bleeding. Allows the healer to restore a small amount of "WOUND" type damage | M35: Battle Tactics II: your can add your battle roll score when performing combat teamwork tactics or, in case that the user is the combat leader: looking for team-type combat oportunities. However, please beware that this only works if the group is willingly working together and has some means to comunicate or has time to perform some adjustments. Team type combat oportunities can only be taken when the leader has a Battle skill on this same level at the very least | V35: Magic Exec II: you can now interact with structural magical objects such as elevators, magic aparatus and other magic objects which are not in the tool or human-class type (objects made to be worn by humans). You are still limited to interact with "useable" and "non bonded" magic structures. Please keep in mind that some magic aparatus such as transportation devices (teleport facility), requiere large amount of mana to work. it takes 10-20 rounds to sync with newly met magical objects, however, it will take usually 1-3 rounds after the first time (depending on the object complexity). | AE35: Mana Trigger II: As a Full-Round Action, you can enter a ManaTrance with a DC 10 mana sensitivity check. In this state, you remain fully aware of your surroundings. Each hour you remain in the trance, you regain a number of Mana Points equal to your Mana Sensitivity Level (max 10)
D36: Patching III : you can perform Patching outside of a "short rest" instance by spending 10 minutes in performing a total focus action, the user is completly prone during that time, and will remain prone during 3 rounds after suspending treatment. However, the target must abide by a non-intensive physical action policy, otherwise the effect will be voided and the target must be healed again with heavy penalty, HP recovered in this way is only "temporarily" recovered until the hour time has passed which is when the recovery becomes permanent | M36: Battle Tactics III: When you are in a disvantageous tactical circumstance you can reduce the imposed penalty by quickly adapting to it and adjusting your actions acordingly. If you perform the appropiate actions, then, reduce the penalty imposed by the combat disvantage | V36: Magic Exec III: you can de-activate and interrupt the use of most "non-useable" magical objects, these objects will normally trigger by themselves but you are capable of trigger them down, most of the time this means the expenditure of MP to interrupt the flow of mana of the object. it takes from 5-10 rounds to interrupt a magical object and you need to be in contact with it or its magical core. Also, please keep in mind that even non-useable magical objects are made to be worn by humans, this skill does not allow the user to interact with "autonomous" and "independent" magical objects such as golems and magic traps | AE36: Magic Trigger III: As a Full round action, you can enter into total defense mode where you obtain +5 to your mana saving roll, this is provided that you can actually move and react to it. This action reflects the user attunement to the mana so high that he can react instinctively to mana based attacks and dodge as if he knew the attack was comming beforehand.
D37: Note: Healing[C] cannot treat someone with "Serious wounds"(R4) or worse | M37: *note: Battle[c] can be used in both Large scale battle and normal combat, but its effects are different for both, the effects described here detail about its use in "normal combat" | V37: *note: Useable items are magical items which accept external inputs, for example, a ring of protection is a "non-useable" item as it provides a constant magical bonus, and there is no manipulation from the user toward the ring, in simple terms, the ring simply works by putting it on your finger and there is no enabling or disabling. Viceversa, a useable item such as a magic wand needs the user to activate and sometimes guide its powers | AE37: *note2: Mana sensitivity has a base cost of 3 MP per use for the unskilled person who has learned it recently
C38: Evolution: | L38: Evolution: | V38: *note2: please keep in mind that any magical object that has not been sync with the user in a time equal to a 1 day (4 TU) will count as a new magical object | AD38: Evolution:
D39: Combat Aid(T1) | M39: Combat Coordination (T1) | U39: Evolution: | AE39: Mana Body (T1)
D40: Treatment(T2) | M40: Skirmirsher (T2) | V40: Multi-Magic Object (T1) | AE40: Mana Trance (T1)
D41: Diagnose (T3) | M41: Leadership (T3) | V41: MagicShieldUser (T1) | AE41: Mana Sense (T2)
D42: Oriental Healing (Rare) | M42: Guerrilla Warfare (Rare) | V42: Scrying Eye (T1) | AE42: Mana Attunement (T2)
C43: Perform(1-4) | L43: Perform(1-4) | V43: WandWielder (T2) | AE43: Superior Mana Sensitivity (T3)
D44: Start - Recover 1k1 HP of health | M44: Start - Detect Combat Oportunities | V44: Magic Devise Operation (T2) | AD44: Perform(1-4)
...

Sheet Sheet3
C5: Basic lv struct
C7: 1. Action open - raise 1 | G7: 1 | H7: Raise 1 | J7: Patching : During a "Short Rest" (aprox 2hrs) period, you can recover additional (1k1) to target, it works only once per target after any "Long Rest" (8hrs), multiple healings cannot be stacked together. You can only heal as many as your WILL/50 people during a single short rest, while still resting yourself. otherwise, you can manage twice as much people but with no rest and adding a permanent fatigue penalty debuff | N7: 10's Explode | R7: Combat focus - resist fear and cohesion based spirit attacks automatically when in battle
C8: 2. Skill check+1 - | R8: C. Focus II - when in combat defend against distractions automatically
C9: 3. Skill performance+1 - item allowance | G9: 2 | H9: Skill Check +1 | J9: Meding Effect I: mend bleeding wounds and stabilize health hazards or injuries ranked "minor"(R1) as base (more by performing raises)
C10: 4. Skill check+2 - | R10: Skill Check 1k0+3
C11: 5. Skill Prof - Greater Check+1 | G11: 3 | H11: SKILL PROF 1: Healing Item | J11: Skill Crit 1: On a skill check of 40 or more, add targets +VIT/2 to healing and mend one rank higher of wounds (max: serious wounds)
C12: Skill becomes upgradeable 1 | R12: Raise 2
C13: 6. 1st Feat Requiered | G13: 4 | H13: Skill Check +2 | J13: Meding Effect II: mend bleeding wounds and stabilize health hazards, only injuries ranked from "Minor"(R1) to "Light"(R2) as base (more by performing raises)
C14: Action Enhance - greater perform | R14: 2. Skill Crit: On a skill check of 40 or more, add +10 to Resist Score
C15: 7. Skill performance+2 - raise 2 | G15: 5 | H15: Skill Check 1k0+2 | N15: SKILL UPGRADE I | R15: 3. Resist by 15
C16: Skill becomes upgradeable 2 | R16: G.Perf - Reaction: you gain a +5 morale bonus on attack rolls and weapon damage rolls the fear affect on you for 1 round. Non Stackable
C17: 8. Skill check+3 - attributes skill restric
C18: 9. Skill performance+4 - | H18: REQUIERES 1st FEAT
C19: Skill becomes upgradeable 3 | G19: 6 | H19: Skill Check 1k0+3 | J19: Patching II : you can perform Patching outside of a "short rest" instance by spending 10 minutes in performing a total focus action, the user is completly prone during that time, and will remain prone during 3 rounds after suspending treatment. However, the target must abide by a non-intensive physical action policy, otherwise the effect will be voided and the target must be healed again with heavy penalty, HP recovered in this way is only "temporarily" recovered until the hour time has passed which is when the recovery becomes permanent
C20: 10. 2nd Feat Requiered | R20: Acrobacia | T20: Lv 1 [8]
C21: Skill prof+, Mastery perk, Greater Check+2 | G21: 7 | H21: Raise 2 | J21: G. Enhace: Recover additional health by target +Vit score | N21: SKILL UPGRADE II | R21: 1k0+3 | S21: Skill Actions:
S22: ActionMan - perform enhanced physical action such as Running, Jumping, etc. After the action there is a temporal fatigue debuff of 1 dice penalty, stackable
S23: ActionMan II - you can perform a extended Athetism action, until you stop there is no sudden fatigue penalty. Stopping means to have one round where you do not perform athetism actions or you fail your athetism skill check
H24: REQUIERES 2nd FEAT | R24: Check | S24: JumpMan -
G25: 8 | H25: Skill Check 1k0+4 | J25: Meding Effect III: mend bleeding wounds and stabilize health hazards, only injuries ranked from "Minor"(R1) to "Moderate"(R3) as base (more by performing raises) | R25: 2 | S25: Skill Traits
S26: - Improve 75% of physical action
G27: 9 | H27: SKILL PROF 2: Healing Item | J27: Skill Crit 2: On a skill check of 50 or more, add targets +VIT to healing and Gains a Free Raise when rolling effect | N27: SKILL UPGRADE III | R27: Raises | S27: - Reduces the amount of Fatigue produced by a Highly physical action
R28: 10's | S28: Trigger
S29: Skill Crit: On a skill check of 40 or more, add +50% to physical action performance
H30: REQUIERES Master FEAT | R30: Explode | S30: Athletism Item: Specific footwear item can boost athletism
G31: 10 | H31: Skill Check 2k0+5 | N31: Mastery PERK
R33: Martial Temperance | T33: Lv 1 [10]
R34: 1k0+4 | S34: Skill Actions:
S35: ActionMan - perform enhanced physical action such as Running, Jumping, etc. After the action there is a temporal fatigue debuff of 1 dice penalty, stackable
S36: ActionMan II - you can perform a extended Athetism action, until you stop there is no sudden fatigue penalty. Stopping means to have one round where you do not perform athetism actions or you fail your athetism skill check
R37: Check | S37: JumpMan -
R38: 2 | S38: Skill Traits
S39: - Improve 75% of physical action
R40: Raises | S40: - Reduces the amount of Fatigue produced by a Highly physical action
R41: 10's | S41: Trigger
S42: Skill Crit: On a skill check of 40 or more, add +50% to physical action performance
R43: Explode | S43: Athletism Item: Specific footwear item can boost athletism

Sheet BasicSkills
A1: 1 | B1: Athletism | C1: AGI | D1: Support | E1: Root | F1: the simple handling of your body nimbleness including general cardio and gymnastics
A2: 2 | B2: Dismantle | C2: AGI | D2: Support | E2: Root | F2: proficiency into dismantling plants, animals and monsters to extract ingredients and byproducts
A3: 3 | B3: Hide | C3: AGI | D3: Support | E3: Root | F3: the ability to hide efficiently, it only allows to hide without movement
A4: 4 | B4: Riding | C4: AGI | D4: Support | E4: Root | F4: the proficiency into using horses and other similar land riding mounts
A5: 5 | B5: Sleight of Hand | C5: AGI | D5: Support | E5: Root | F5: the use of hand deft movements in cunning ways to peform hand tricks
A6: 6 | B6: Acting | C6: CAR | D6: Support | E6: Root | F6: performing a complete interpretation of a pre-made role/script
A7: 7 | B7: Animal Empathy | C7: CAR | D7: Support | E7: Root | F7: the ability to deal with animals and manage them without the use of force
A8: 8 | B8: Bluff | C8: CAR | D8: Support | E8: Root | F8: proficiency in lying, flattering or gaslighting others in social environments
A9: 9 | B9: Diplomacy | C9: CAR | D9: Support | E9: Root | F9: the ability to mediate or converse in a formal manner in social environments
A10: 10 | B10: Haggle | C10: CAR | D10: Support | E10: Root | F10: the ability to negotiate the trade of goods or advantages in a social environment
A11: 11 | B11: Intimidation | C11: CAR | D11: Support | E11: Root | F11: the ability to threaten others by using simple words and bodily language
A12: 12 | B12: Perform | C12: CAR | D12: Support | E12: Root | F12: the ability to express yourself with body language and produce basic music improvising with sounds
... A55: 55 | B55: Still Mind, Focus | C55: WIL | D55: Core | E55: Root | F55: The main proficiency for self discipline and attaining clarity on combat

Sheet InterSkills
A1: Monster Carver (Basic) | B1: AGI | C1: Support | D1: Dismantle | E1: monster carver is the person who skins and extract every monster part to ensure maximun efficiency and that there is not any loss, unlike a dismantler a carver is capable of dismembering higher ranked monsters with tough skin and poisonous blood until its all usable, however, it needs special tools for diferent monsters
A2: Salvaging (Lesser) | B2: AGI | C2: Support | D2: Dismantle | E2: The skill to reclaim and restore, damaged structures and property without damaging them. In simplified terms allows to extract useful and expensive parts from dificult locations in order to sell or reuse them, also, it is specially important in either magical vessels recovery or a sea ship's recovery of their cargo as only a salvaging expert is capable of recovering sensitive materials in good conditions.
A3: Scavanging | B3: AGI | C3: Support | D3: Dismantle | E3: scavaning is an ability to loot and seek throughly for any usable items in a very efficient manner, the user is like a hound looking everywhere and everything for items to loot, its a skill that increases the both the amount of loot and more
A4: Camoflague (Intermediate) | B4: AGI | C4: Support | D4: Hide | E4: a rare version of hide, which adds the use of natural enviroment coverage to a greater effectivity in adition to hide basic cover qualities, it increases the cover value of a specific natural speciality which choosen upon taken this skill
A5: Cloak and Dagger (Intermediate) | B5: AGI | C5: Support | D5: Hide | E5: the ability to perform acts of questionable nature and hide your trail, the skill is useful to counter investigation skills
A6: Hide in Plain Sight (Basic) | B6: AGI | C6: Support | D6: Hide | E6: the ability to hide in plain sight by blending with the surroundings, this means that instead of hiding by using a cover the user is capable of blending with the active environment by performing actions which are appropiate to fit in with the surroundings, hide in plain sight is greatly influenced by the user outward appereance+C62
A7: Escapist (Inter) | B7: AGI | C7: Support | D7: Sleight of Hand | E7: the skil to escape from binds such as ropes chain or simple grappling
A8: Prestidigitation | B8: AGI | C8: Support | D8: Sleight of Hand | E8: refers to fine motor skills when used by performing artists in different art forms to entertain or manipulate. It is closely associated with close-up magic, card magic, card flourishing and stealing. Because of its heavy use and practice by magicians, sleight of hand is often confused as a branch of magic
A9: Thievery | B9: AGI | C9: Support | D9: Sleight of Hand | E9: The ability to substract elements from a person without his knowledge, its a classic
A10: Beast Trainer | B10: CAR | C10: Support | D10: Animal Empathy | E10: the ability to train beasts of different types, it will increase the INT of the animals and allows the user to teach them tricks
A11: BeastMaster | B11: CAR | C11: Support | D11: Animal Empathy | E11: the ability to manage and control beast creatures, it allows to manage and care for these animals and increases their loyalty to the user
A12: Falconeer | B12: CAR | C12: Support | D12: Animal Empathy | E12: the ability to manage and control flying creatures, it allows to manage and care for these animals and increases their loyalty to the user
... A135: Tower Soldier Technique | B135: STR | C135: Core | D135: Melee Weapons | E135: the techique used by profesional heavy soldiers, who wield large weapons along with heavy armor. This is an entry level skill which uses only non-exotic two handed weapons such as great hammer, great sword, and heavy spear, it offers bonus while using heavy armor
A136: Sprinter | B136: =VLOOKUP(D136,BasicSkills!$B$1:$E$55,2,FALSE) -> AGI | C136: =VLOOKUP(D136,BasicSkills!$B$1:$E$55,3,FALSE) -> Support | D136: Athletism | E136: a skill focusing athletic capacity into sprinting and running
A137: Fitness | B137: =VLOOKUP(D137,BasicSkills!$B$1:$E$55,2,FALSE) -> AGI | C137: =VLOOKUP(D137,BasicSkills!$B$1:$E$55,3,FALSE) -> Support | D137: Athletism | E137: a skill focusing athletic ability into extended fitness and endurance
A138: WarHorse | B138: =VLOOKUP(D138,BasicSkills!$B$1:$E$55,2,FALSE) -> AGI | C138: =VLOOKUP(D138,BasicSkills!$B$1:$E$55,3,FALSE) -> Support | D138: Riding | E138: the skill used to ride high ranking horses such as trained warhorses and similar trained mounts
A139: Equestry | B139: =VLOOKUP(D139,BasicSkills!$B$1:$E$55,2,FALSE) -> AGI | C139: =VLOOKUP(D139,BasicSkills!$B$1:$E$55,3,FALSE) -> Support | D139: Riding | E139: the skill to perform all manners of manuvers while riding a mount
A140: Showman | B140: =VLOOKUP(D140,BasicSkills!$B$1:$E$55,2,FALSE) -> CAR | C140: =VLOOKUP(TRIM(D140),BasicSkills!$B$1:$E$55,3,FALSE) -> Support | D140: Acting | E140: the skill to draw atention and "act" in way that entertains the public
A141: Theatre | B141: =VLOOKUP(D141,BasicSkills!$B$1:$E$55,2,FALSE) -> CAR | C141: =VLOOKUP(D141,BasicSkills!$B$1:$E$55,3,FALSE) -> Support | D141: Acting | E141: the skill to perform acting in a established setting with greater inmersion
A142: Musical Instrument | B142: =VLOOKUP(D142,BasicSkills!$B$1:$E$55,2,FALSE) -> CAR | C142: =VLOOKUP(D142,BasicSkills!$B$1:$E$55,3,FALSE) -> Support | D142: Perform | E142: the skill needed to perform with a musical instrument
A143: Singing | B143: =VLOOKUP(D143,BasicSkills!$B$1:$E$55,2,FALSE) -> CAR | C143: =VLOOKUP(D143,BasicSkills!$B$1:$E$55,3,FALSE) -> Support | D143: Perform | E143: the skill needed to perform with a singing voice, skill does not guarantee the actual voice quality
A144: Dancing | B144: =VLOOKUP(D144,BasicSkills!$B$1:$E$55,2,FALSE) -> CAR | C144: =VLOOKUP(D144,BasicSkills!$B$1:$E$55,3,FALSE) -> Support | D144: Perform | E144: the skill needed to perform using body expression and similar dancing moves
A145: Anomaly Sense | B145: =VLOOKUP(D145,BasicSkills!$B$1:$E$55,2,FALSE) -> CAR | C145: =VLOOKUP(D145,BasicSkills!$B$1:$E$55,3,FALSE) -> Support | D145: Spirit Sensitivity | E145: the skill needed to perceive supernatural begins in a more consise way, still its erratic and cannot "see" spirits
A146: Karmic Bond | B146: =VLOOKUP(D146,BasicSkills!$B$1:$E$55,2,FALSE) -> CAR | C146: =VLOOKUP(D146,BasicSkills!$B$1:$E$55,3,FALSE) -> Support | D146: Spirit Sensitivity | E146: the skill needed to bond with a spirit and feel the bonding in some degree
A147: Metalwork | B147: =VLOOKUP(D147,BasicSkills!$B$1:$E$55,2,FALSE) -> INT | C147: =VLOOKUP(D147,BasicSkills!$B$1:$E$55,3,FALSE) -> Support | D147: Craft | E147: the skill neded to work on metal on a very rudimentary way, similar to making horseshoes or simle cookign utencils
A148: Woodwork | B148: =VLOOKUP(D148,BasicSkills!$B$1:$E$55,2,FALSE) -> INT | C148: =VLOOKUP(D148,BasicSkills!$B$1:$E$55,3,FALSE) -> Support | D148: Craft | E148: the skill neded to work on wood on a rough way, good for making simple furniture and basic wood tools
A149: Gumption | B149: =VLOOKUP(D149,BasicSkills!$B$1:$E$55,2,FALSE) -> INT | C149: =VLOOKUP(D149,BasicSkills!$B$1:$E$55,3,FALSE) -> Support | D149: Culture Lore | E149: the skill to understand the way people think within a certain zone, it allows you use local customs and prejudices to your advantage
A150: Folklore | B150: =VLOOKUP(D150,BasicSkills!$B$1:$E$55,2,FALSE) -> INT | C150: =VLOOKUP(D150,BasicSkills!$B$1:$E$55,3,FALSE) -> Support | D150: Culture Lore | E150: the lore of the folk, it lets you understand the common knowledge shared among the locals in a zone including their myths and trends
A151: Repairs | B151: =VLOOKUP(D151,BasicSkills!$B$1:$E$55,2,FALSE) -> INT | C151: =VLOOKUP(D151,BasicSkills!$B$1:$E$55,3,FALSE) -> Support | D151: Mechanics | E151: the skill to repair mechanical items, but it cannot repair destroyed ones
A152: Mechanic Operation | B152: =VLOOKUP(D152,BasicSkills!$B$1:$E$55,2,FALSE) -> INT | C152: =VLOOKUP(D152,BasicSkills!$B$1:$E$55,3,FALSE) -> Support | D152: Mechanics | E152: the skill needed to operate mechanical devises such as vehicles or simple machines
... A181: Pathfinder | B181: =VLOOKUP(D181,BasicSkills!$B$1:$E$55,2,FALSE) -> WIL | C181: =VLOOKUP(D181,BasicSkills!$B$1:$E$55,3,FALSE) -> Support | D181: Wayfarer | E181: a skill focused on finding lost paths in treacherous roads

Sheet GroupvsSkills
A1: ACADEMIC | B1: Investigation | C1: PER
A2: ACADEMIC | B2: Knowledge (Specific) | C2: INT
A3: ACADEMIC | B3: Linguistics | C3: INT
A4: ARTISAN | B4: Apraisal | C4: PER
A5: ARTISAN | B5: Craft | C5: INT
A6: ARTISAN | B6: Minning | C6: STR
A7: BARD | B7: Diplomacy | C7: CAR
A8: BARD | B8: Mana Sensitivity | C8: WIL
A9: BARD | B9: Melee Weapons Handling | C9: STR
A10: BARD | B10: Perform | C10: CAR
A11: BARD | B11: Sleight of Hand | C11: AGI
A12: BRAWLER | B12: Athletism | C12: AGI
... A100: WITCH | B100: Spirit Sensitivity | C100: CAR

Sheet SkillGroup
A1: ACADEMIC | B1: SUPPORT | C1: INT
A2: ARTISAN | B2: SUPPORT | C2: INT
A3: BUTCHER | B3: SUPPORT | C3: STR
A4: ENGINEER | B4: SUPPORT | C4: INT
A5: FARMER | B5: SUPPORT | C5: WIL
A6: HIGH CLASS | B6: SUPPORT | C6: CHA
A7: HUNTER | B7: SUPPORT | C7: PER
A8: LAWMAKER | B8: SUPPORT | C8: WIL
A9: LOW CLASS | B9: SUPPORT | C9: PER
A10: MERC | B10: SUPPORT | C10: STR
A11: MERCHANT | B11: SUPPORT | C11: PER
A12: MINSTREL | B12: SUPPORT | C12: PER
... A28: WARRIOR | B28: CORE | C28: STR

Sheet Sheet6
A1: - Basic Array Mastery | D1: Formal Magics 8 | I1: =MID(A1,4,LEN(A1)) -> Basic Array Mastery | J1: =VLOOKUP(MID(D1,1,LEN(D1)-2),BasicSkills!$B$1:$E$55,2,FALSE) -> INT | K1: =VLOOKUP(MID(D1,1,LEN(D1)-2),BasicSkills!$B$1:$E$55,3,FALSE) -> Support | L1: =TRIM(MID(D1,1,LEN(D1)-2)) -> Formal Magics | M1: =A2 -> the ability to peform basic arrays, allowing a wide range of applications in magic based cultures, including the making of semi-permanent magic circles
A2: the ability to peform basic arrays, allowing a wide range of applications in magic based cultures, including the making of semi-permanent magic circles
A3: - Witchcraft | D3: Formal Magics 7 | I3: =MID(A3,4,LEN(A3)) -> Witchcraft | J3: =VLOOKUP(MID(D3,1,LEN(D3)-2),BasicSkills!$B$1:$E$55,2,FALSE) -> INT | K3: =VLOOKUP(MID(D3,1,LEN(D3)-2),BasicSkills!$B$1:$E$55,3,FALSE) -> Support | L3: =TRIM(MID(D3,1,LEN(D3)-2)) -> Formal Magics | M3: =A4 -> The ancient art of witchcraft as explained by the kabbalistic witches of the modern era, its rich in occult knowledge relating to nature and magic
A4: The ancient art of witchcraft as explained by the kabbalistic witches of the modern era, its rich in occult knowledge relating to nature and magic
A5: - Basic Magic Theory | D5: Spellcraft 9 | I5: =MID(A5,4,LEN(A5)) -> Basic Magic Theory | J5: =VLOOKUP(MID(D5,1,LEN(D5)-2),BasicSkills!$B$1:$E$55,2,FALSE) -> PER | K5: =VLOOKUP(MID(D5,1,LEN(D5)-2),BasicSkills!$B$1:$E$55,3,FALSE) -> Support | L5: =TRIM(MID(D5,1,LEN(D5)-2)) -> Spellcraft | M5: =A6 -> the ability to study, disect and understand magic, its a rather technical skill used to obtain understanding magic and the laws of the world
A6: the ability to study, disect and understand magic, its a rather technical skill used to obtain understanding magic and the laws of the world
A7: - SpellBreaker | D7: Spellcraft 8 | I7: =MID(A7,4,LEN(A7)) -> SpellBreaker | J7: =VLOOKUP(MID(D7,1,LEN(D7)-2),BasicSkills!$B$1:$E$55,2,FALSE) -> PER | K7: =VLOOKUP(MID(D7,1,LEN(D7)-2),BasicSkills!$B$1:$E$55,3,FALSE) -> Support | L7: =TRIM(MID(D7,1,LEN(D7)-2)) -> Spellcraft | M7: =A8 -> the ability to break magic apart by understanding its estructure and composition, this specialized skill would allow a non-mage to counter magic using basic physical components
A8: the ability to break magic apart by understanding its estructure and composition, this specialized skill would allow a non-mage to counter magic using basic physical components
A9: - Battlecraft | D9: Spellcraft 7 | I9: =MID(A9,4,LEN(A9)) -> Battlecraft | J9: =VLOOKUP(MID(D9,1,LEN(D9)-2),BasicSkills!$B$1:$E$55,2,FALSE) -> PER | K9: =VLOOKUP(MID(D9,1,LEN(D9)-2),BasicSkills!$B$1:$E$55,3,FALSE) -> Support | L9: =TRIM(MID(D9,1,LEN(D9)-2)) -> Spellcraft | M9: =A10 -> the ability to use and apply magic during battle in a efficient manner, it makes the casting of magic more efficient by adjusting the user to chaotic enviroments, its a nesesary skill for mage knights
A10: the ability to use and apply magic during battle in a efficient manner, it makes the casting of magic more efficient by adjusting the user to chaotic enviroments, its a nesesary skill for mage knights
